<?xml version="1.0" ?>
<robot xmlns:xacro="http://www.ros.org/wiki/xacro">

	<xacro:include filename="$(find description)/macros/roller.xacro"/>

	<xacro:macro
		name="rim_macro"
		params="name color xyz rpy">

		<link name="rim_${name}_link">

			<inertial>

				<origin xyz="0 0 -0.000343"/>
				<mass value="0.00835758"/>
				<inertia
					ixx="6.63684e-07"
					ixy="0"
					ixz="0"
					iyy="6.63684e-07"
					iyz="0"
					izz="9.40333e-07"
				/>

			</inertial>
			<visual>

				<geometry>

					<mesh filename="package://description/mesh/wheelasm.stl"/>

				</geometry>
				<material name="rim_${name}_material">

					<color rgba="${color} 1"/>

				</material>

			</visual>
			<collision>

				<geometry>

					<mesh filename="package://description/mesh/wheelasm.stl"/>

				</geometry>

			</collision>

		</link>
		<joint
			name="rim_${name}_joint"
			type="continuous"
		>

			<parent link="base_link" />
			<child link="rim_${name}_link" />
			<axis xyz="0 0 1"/>
			<origin
				xyz="${xyz}"
				rpy="${rpy}"/>
		</joint>

		<xacro:roller_macro
			parent="${name}"
			name="one"
			xyz="0.01355 0 0.0055"
			rpy="-1.570796326794896 0 0"/>
	</xacro:macro>

</robot>
